<?xml version="1.0"?>

<!-- Author : Cyril Lugan -->

<robot xmlns:sensor="http://playerstage.sourceforge.net/gazebo/xmlschema/#sensor"
	xmlns:controller="http://playerstage.sourceforge.net/gazebo/xmlschema/#controller"
	xmlns:interface="http://playerstage.sourceforge.net/gazebo/xmlschema/#interface"
	xmlns:xacro="http://ros.org/wiki/xacro">

	<include filename="$(find irl_common_description)/urdf/common.xacro" />

	<!-- Macro for a static kinect (fixed camera joint) -->
	<xacro:macro name="kinect_static" params="name parent xyz rpy angle">

		<xacro:kinect_links
			name="${name}" parent="${parent}"
			xyz="${xyz}" rpy="${rpy}"
			/>

		<joint name="${name}_camera_joint" type="fixed">
			<origin xyz="0 0 0.02" rpy="0 ${angle} 0" />
			<parent link="${name}_base_link"/>
			<child link="${name}_camera_link"/>
		</joint>

	</xacro:macro>

	<!--
		Macro for a moving kinect (camera joint controlled)
		
		WARNING : Camera angle given by the kinect is relative to the horizon,
			  not the base!
			  There is no way to retrieve the base orientation, that's why
			  this model will work only if the base is parallel with the
			  ground.

		More informations on
		http://openkinect.org/wiki/Protocol_Documentation#Motor_Initialization
	-->
	<xacro:macro name="kinect" params="name parent xyz rpy">

		<xacro:kinect_links
			name="${name}" parent="${parent}"
			xyz="${xyz}" rpy="${rpy}"
			/>

		<joint name="${name}_camera_joint" type="revolute">
			<axis xyz="0 -1 0"/>
			<!--
				According to open kinect
				+31 degrees (up) and -31 degrees (down)
			-->
			<limit lower="${-0.541}" upper="${0.541}" effort="15" velocity="5" /> <!-- random effort/velocity -->
			<origin xyz="0 0 0.02" rpy="0 0 0" />
			<parent link="${name}_base_link"/>
			<child link="${name}_camera_link"/>
		</joint>

	</xacro:macro>

	<!-- (private) A grey cylinder to display an optical frame in rviz -->
	<xacro:macro name="kinect_optical_frame" params="name">
		<link name="${name}">
			<inertial>
				<mass value="0.001" />
				<origin xyz="0 0 0" rpy="0 0 0" />
				<inertia ixx="0.0001" ixy="0" ixz="0" iyy="0.000001" iyz="0" izz="0.0001" />
			</inertial>
			<visual>
				<origin xyz="0 0 0.001" rpy="0 0 0" />
				<geometry>
					<cylinder length="0.06" radius="0.01" />
				</geometry>
				<material name="OpticalGrey">
					<color rgba="0.5 0.5 0.5 1.0"/>
				</material>
			</visual>
			<collision>
				<origin xyz="0 0 0" rpy="0 0 0" />
				<geometry>
					<cylinder length="0.06" radius="0.01" />
				</geometry>
			</collision>
		</link>
	</xacro:macro>

	<!-- (private) Everything but the camera joint -->
	<xacro:macro name="kinect_links" params="name parent xyz rpy">

		<joint name="${name}_base_joint" type="fixed">
			<origin xyz="${xyz}" rpy="${rpy}" />
			<parent link="${parent}"/>
			<child link="${name}_base_link"/>
		</joint>

		<link name="${name}_base_link">
			<inertial>
				<mass value="0.001" />
				<origin xyz="0 0 0" rpy="0 0 0" />
				<inertia ixx="0.0001" ixy="0" ixz="0" iyy="0.000001" iyz="0" izz="0.0001" />
			</inertial>
			<visual>
				<geometry>
					<box size="0.06 0.08 0.02" />
				</geometry>
				<material name="KinectBlack">
					<color rgba="0 0 0 1.0"/>
				</material>
			</visual>
			<collision>
				<origin xyz="0 0 0" rpy="0 0 0" />
				<geometry>
					<box size="0.06 0.08 0.02" />
				</geometry>
			</collision>
		</link>

		<!-- Missing joint here, defined in kinect.urdf.xacro -->

		<link name="${name}_camera_link">
			<inertial>
				<mass value="0.001" />
				<origin xyz="0 0 0" rpy="0 0 0" />
				<inertia ixx="0.0001" ixy="0" ixz="0" iyy="0.000001" iyz="0" izz="0.0001" />
			</inertial>
			<visual>
				<origin xyz="0 0 0.02" rpy="0 0 0" />
				<geometry>
					<box size="0.06 0.26 0.035" />
				</geometry>
				<material name="KinectBlack">
					<color rgba="0 0 0 1.0"/>
				</material>
			</visual>
			<collision>
				<origin xyz="0 0 0" rpy="0 0 0" />
				<geometry>
					<box size="0.06 0.26 0.035" />
				</geometry>
			</collision>
		</link>

		<xacro:kinect_optical_frame name="${name}_depth_optical_frame"/>
		<xacro:kinect_optical_frame name="${name}_rgb_optical_frame"/>

		<joint name="${name}_depth_optical_joint" type="fixed">
			<origin xyz="0 0.012 0.02" rpy="${-M_PI/2} 0 ${-M_PI/2}" />
			<parent link="${name}_camera_link" />
			<child link="${name}_depth_optical_frame" />
		</joint>

		<joint name="${name}_rgb_optical_joint" type="fixed">
			<origin xyz="0.025 0 0" rpy="0 0 0" />
			<parent link="${name}_depth_optical_frame" />
			<child link="${name}_rgb_optical_frame" />
		</joint>

	</xacro:macro>

</robot>
