<?xml version="1.0"?>
<robot xmlns:sensor="http://playerstage.sourceforge.net/gazebo/xmlschema/#sensor"
       xmlns:controller="http://playerstage.sourceforge.net/gazebo/xmlschema/#controller"
       xmlns:interface="http://playerstage.sourceforge.net/gazebo/xmlschema/#interface"
       xmlns:xacro="http://ros.org/wiki/xacro">

	<include filename="$(find irl_common_description)/urdf/common_geometry.xacro" />
	<include filename="$(find irl_common_description)/urdf/actuators/pan_tilt_ptu46175.transmission.xacro" />

	<!-- (private) Generic pan tilt link -->
	<xacro:macro name="_pan_tilt_ptu46175_link" params="name xyz rpy mesh mass">
		<link name="${name}">
			<xacro:simple_inertial mass="${mass}" />
			<visual>
				<origin xyz="${xyz}" rpy="${rpy}" />
				<geometry>
					<mesh filename="package://irl_common_description/meshes/actuators/pan_tilt_ptu46175/${mesh}.dae"  />
				</geometry>
			</visual>
			<collision>
				<origin xyz="${xyz}" rpy="${rpy}" />
				<geometry>
					<mesh filename="package://irl_common_description/meshes/actuators/pan_tilt_ptu46175/${mesh}.stl"  />
				</geometry>
			</collision>
		</link>
	</xacro:macro>

	<xacro:macro name="pan_tilt_ptu46175" params="name parent offset_x offset_y offset_z">

		<joint name="${name}_fixed_joint" type="fixed">
			<parent link="${parent}"/>
			<child link="${name}_tilt_link"/>
			<origin xyz="${offset_x} ${offset_y} ${offset_z}" rpy="0 0 0" />
		</joint>

		<xacro:_pan_tilt_ptu46175_link
			name="${name}_tilt_link"
			xyz="-0.07 0.045 0"
			rpy="0 0 -${M_PI/2}"
			mass="0.2"
			mesh="tilt"
			/>

		<joint name="${name}_tilt_joint" type="revolute">
			<parent link="${name}_tilt_link"/>
			<child link="${name}_pan_link"/>
			<origin xyz="0 0 0.045" rpy="0 0 0" />
			<axis xyz="0 0 1" rpy="0 0 0"/>
			<limit effort="100" velocity="0.1" lower="-0.7" upper="0.7" />
		</joint>

		<xacro:_pan_tilt_ptu46175_link
			name="${name}_pan_link"
			xyz="-0.07 0.02 0"
			rpy="0 0 -${M_PI/2}"
			mass="0.001"
			mesh="pan"
			/>

		<joint name="${name}_pan_joint" type="revolute">
			<parent link="${name}_pan_link"/>
			<child link="${name}_bracket_link"/>
			<origin xyz="${0.025/2} ${0.065/2} 0.04" rpy="${M_PI/2} 0 ${-M_PI/2}" />
			<axis xyz="1 0 0" rpy="0 0 0"/>
			<limit effort="100" velocity="0.1" lower="-0.7854" upper="0.7854" />
		</joint>

		<xacro:_pan_tilt_ptu46175_link
			name="${name}_bracket_link"
			xyz="0 0 0"
			rpy="0 0 0"
			mass="0.001"
			mesh="bracket"
			/>

		<joint name="${name}_top_fixed_joint" type="fixed">
			<parent link="${name}_bracket_link"/>
			<child link="${name}_top"/>
			<origin xyz="0 0 0.05" rpy="0 0 0" />
		</joint>
		<link name="${name}_top" />

		<xacro:pan_tilt_ptu46175_tilt_transmission name="${name}_tilt_trans"/>
		<xacro:pan_tilt_ptu46175_pan_transmission name="${name}_pan_trans"/>

	</xacro:macro>


</robot>
