<?xml version="1.0"?>
<robot xmlns:sensor="http://playerstage.sourceforge.net/gazebo/xmlschema/#sensor"
       xmlns:controller="http://playerstage.sourceforge.net/gazebo/xmlschema/#controller"
       xmlns:interface="http://playerstage.sourceforge.net/gazebo/xmlschema/#interface"
       xmlns:xacro="http://ros.org/wiki/xacro">
	
	<!-- Include files for extansions -->
	<include filename="$(find johnny_0_description)/urdf/wheel/wheel.gazebo.xacro" />
	<include filename="$(find johnny_0_description)/urdf/wheel/wheel.transmission.xacro" />

	<xacro:macro name="wheel" params="side reflectSide face reflectFace parent">
		
		<joint name="wheel${side}${face}_fixed_joint" type="fixed">
			<parent link="${parent}"/>
			<child link="wheel${side}${face}_link"/>
			<origin xyz="${reflectFace*0.17} ${reflectSide*0.17} -0.133645" rpy="0 0 ${reflectSide*(M_PI/4+(1-reflectFace)*M_PI/4)}" />
		</joint>

		<link name="wheel${side}${face}_link">

			<inertial>
				<mass value="0.5" />
				<origin xyz="0 0 0" />
				<inertia ixx="0" ixy="0" ixz="0"
						 iyy="0" iyz="0" izz="0" />
			</inertial>

			<visual name="wheel${side}${face}_visual">
				<origin xyz="0 0 0" rpy="0 0 0" />
				<geometry name="wheel${side}${face}_visual_geom">
					<box size="0.06436 0.02 0.02" />
				</geometry>
			</visual>

			<collision name="wheel${side}${face}_collision">
				<origin xyz="0 0 0" rpy="0 0 0" />
				<geometry name="wheel${side}${face}_collision_geom">
					<box size="0.06436 0.02 0.02" />
				</geometry>
			</collision>
		</link>
		
		<joint name="wheel${side}${face}_ADE_fixed_joint" type="fixed">
			<parent link="wheel${side}${face}_link"/>
			<child link="wheel${side}${face}_ADE_link"/>
			<origin xyz="0.03218 0  0.12708" rpy="0 0 0" />
		</joint>

		<link name="wheel${side}${face}_ADE_link">

			<inertial>
				<mass value="0.5" />
				<origin xyz="0 0 0" />
				<inertia ixx="0" ixy="0" ixz="0"
						 iyy="0" iyz="0" izz="0" />
			</inertial>

			<visual name="wheel${side}${face}_ADE_visual">
				<origin xyz="0 0 0" rpy="0 0 0" />
				<geometry name="wheel${side}${face}_ADE_visual_geom">
					<cylinder radius="0.03575" length="0.25416"/>
				</geometry>
			</visual>

			<collision name="wheel${side}${face}_ADE_collision">
				<origin xyz="0 0 0" rpy="0 0 0" />
				<geometry name="wheel${side}${face}_ADE_collision_geom">
					<cylinder radius="0.03575" length="0.25416"/>
				</geometry>
			</collision>
		</link>		
		
		<joint name="wheel${side}${face}_revolute_joint" type="revolute">
			<parent link="wheel${side}${face}_ADE_link"/>
			<child link="wheel${side}${face}_ADE2_link"/>
			<origin xyz="0 0 -0.12708" rpy="0 0 0" />
			<axis xyz="0 0 1" rpy="0 0 0"/>
			<limit effort="100" velocity="0.1" lower="-0.7854" upper="0.7854" />

			<calibration reference_position="0.0"/>
		</joint>

		<link name="wheel${side}${face}_ADE2_link">

			<inertial>
				<mass value="0.5" />
				<origin xyz="0.045 0 0" />
				<inertia ixx="0" ixy="0" ixz="0"
						 iyy="0" iyz="0" izz="0" />
			</inertial>

			<visual name="wheel${side}${face}_ADE2_visual">
				<origin xyz="0.045 0 0" rpy="0 0 0" />
				<geometry name="wheel${side}${face}_ADE2_visual_geom">
					<box size="0.03284 0.02 0.02" />
				</geometry>
			</visual>

			<collision name="wheel${side}${face}_ADE2_collision">
				<origin xyz="0.045 0 0" rpy="0 0 0" />
				<geometry name="wheel${side}${face}_ADE2_collision_geom">
					<box size="0.03284 0.02 0.02" />
				</geometry>
			</collision>
		</link>		
		
		<joint name="wheel${side}${face}_wheel_continuous_joint" type="continuous">
			<parent link="wheel${side}${face}_ADE2_link"/>
			<child link="wheel${side}${face}_wheel_link"/>
			<origin xyz="0.07492 0 0" rpy="0 ${-M_PI/2} 0" />
			<axis xyz="0 0 1"/>
		</joint>

		<link name="wheel${side}${face}_wheel_link">

			<inertial>
				<mass value="0.5" />
				<origin xyz="0 0 0" />
				<inertia ixx="0" ixy="0" ixz="0"
						 iyy="0" iyz="0" izz="0" />
			</inertial>

			<visual name="wheel${side}${face}_wheel_visual">
				<origin xyz="0 0 0" rpy="0 0 0" />
				<geometry name="wheel${side}${face}_wheel_visual_geom">
					<cylinder radius="0.07754" length="0.027"/>
				</geometry>
			</visual>

			<collision name="wheel${side}${face}_wheel_collision">
				<origin xyz="0 0 0" rpy="0 0 0" />
				<geometry name="wheel${side}${face}_wheel_collision_geom">
					<cylinder radius="0.07754" length="0.027"/>
				</geometry>
			</collision>
		</link>
		
		<!-- extensions -->
		<xacro:johnny_0_wheel_gazebo side="${side}" face="${face}" />
		<xacro:johnny_0_wheel_transmission side="${side}" face="${face}" />
		<xacro:johnny_0_ADE_transmission side="${side}" face="${face}" />
		
		<gazebo reference="wheel${side}${face}_link">
			<material>Gazebo/Red</material>
		</gazebo>

		<gazebo reference="wheel${side}${face}_ADE_link">
			<material>Gazebo/Green</material>
		</gazebo>

		<gazebo reference="wheel${side}${face}_ADE2_link">
			<material>Gazebo/Red</material>
		</gazebo>

		<gazebo reference="wheel${side}${face}_wheel_link">
			<material>Gazebo/Black</material>
		</gazebo>

	</xacro:macro>


</robot>
