<?xml version="1.0"?>

<!-- XML namespaces -->
<robot xmlns:xacro="http://www.ros.org/wiki/xacro">

	<!-- Things that are needed only for Gazebo (not the physical robot).  These include
	sensor and controller plugin specifications -->
	<xacro:include filename="$(find irl_common_description)/urdf/jn0_arm/forearm/forearm.gazebo.xacro" />
	<xacro:include filename="$(find irl_common_description)/urdf/jn0_arm/forearm/forearm.transmission.xacro" />
	<xacro:include filename="$(find irl_common_description)/urdf/common.xacro" />

	<!-- ============================   forearm   ============================ -->

	<xacro:macro name="johnny_0_forearm" params="side parent reflect *origin">
		
		<!-- Elbow revolute joint : tilt -->
			
		<!--joint name="${side}_elbow_tilt_joint" type="fixed"-->
		<joint name="${side}_elbow_tilt_joint" type="revolute">
		<!--joint name="${side}_elbow_tilt_joint" type="continuous"-->
			<axis xyz="0 0 1"/>
			<xacro:insert_block name="origin" />
			<parent link="${parent}"/>
			<child link="${side}_forearm_link"/>
			
			<!-- This parameters have to be modified -->
			<limit effort="10" velocity="1.0" lower="${-43*M_PI/180}" upper="${70*M_PI/180}" />
            <dynamics damping="0.1"/>
		</joint>

		
		<link name="${side}_forearm_link">
			<inertial>
				<mass value="1.34823795" />
				<origin xyz="0.00109577 0.12665702 0.00567457" rpy="0 0 0"/> 
				<inertia  ixx="0.01000680" 	ixy="0.00014372"  	ixz="-0.00008578"
										iyy="0.00168430" 	iyz="0.00086209"
														izz="0.00967320" />
			</inertial>

			<visual>
				<origin xyz="0 0 0" rpy="0 0 0"/>
				<geometry name="${side}_forearm_link_visual_geom">
					<mesh filename="package://irl_common_description/meshes/jn0_arm/forearm/${side}_forearm_link.dae"  />
				</geometry>
			</visual>

			<collision>
				<origin xyz="0 0 0" rpy="0 0 0"/>
				<geometry name="${side}_forearm_link_collision_geom">
					<!--mesh filename="package://irl_common_description/meshes/arm/forearm/${side}_forearm_link.stl"  /-->
					<sphere radius="0.01" />
				</geometry>
			</collision>
		</link>
		
		<!-- extensions -->
		<xacro:johnny_0_forearm_transmission side="${side}" />
		
	</xacro:macro>


</robot>
