<?xml version="1.0"?>
<robot xmlns:sensor="http://playerstage.sourceforge.net/gazebo/xmlschema/#sensor"
       xmlns:controller="http://playerstage.sourceforge.net/gazebo/xmlschema/#controller"
       xmlns:interface="http://playerstage.sourceforge.net/gazebo/xmlschema/#interface"
       xmlns:xacro="http://ros.org/wiki/xacro">

	<include filename="$(find irl_common_description)/urdf/reddy_arm/arm.transmission.xacro" />
	
	<xacro:macro name="ADE_pitch_shoulder" params="side reflect parent">

		<joint name="ADE_pitch_shoulder${side}_fixed_1_joint" type="fixed">
			<parent link="${parent}"/>
			<child link="ADE_pitch_shoulder${side}_link"/>
			<origin xyz="0 0 0.03" rpy="0 -1.5708 0" />
		</joint>

		<link name="ADE_pitch_shoulder${side}_link">
			<inertial>
				<mass value="0.045" />
				<origin xyz="0 0 0" rpy="0 0 0"/> 
        <inertia  ixx="0.00" ixy="0.00"  ixz="0.00"
                  iyy="0.00" iyz="0.00"
                  izz="0.00" />
			</inertial>

			<visual>
				<origin xyz="0 0 0" rpy="0 0 0" />
				<geometry name="ADE_pitch_shoulder${side}_link_visual_geom">
					<box size="0.047 0.01 0.01" />
				</geometry>
			</visual>

			<collision>
				<origin xyz="0 0 0" rpy="0 0 0 " />
				<geometry name="ADE_pitch_shoulder${side}_link_collision_geom">
					<box size="0.047 0.01 0.01" />
				</geometry>
			</collision>
		</link>

		<joint name="ADE_pitch_shoulder${side}_revolute_joint" type="revolute">
			<parent link="ADE_pitch_shoulder${side}_link"/>
			<child link="ADE_pitch_shoulder${side}_fixation"/>
			<origin xyz="0.0235 0 0" rpy="0 0 0" />
			<axis xyz="0 1 0" rpy="0 0 0"/>
			<limit effort="100" velocity="0.1" lower="-0.7854" upper="0.7854" />

			<!-- calibration reference_position="0.0"/ -->
		</joint>

		<link name="ADE_pitch_shoulder${side}_fixation">
			<inertial>
				<mass value="0.001" />
				<origin xyz="0 0 0" rpy="0 0 0"/> 
        <inertia  ixx="0.00" ixy="0.00"  ixz="0.00"
                  iyy="0.00" iyz="0.00"
                  izz="0.00" />
			</inertial>

			<visual>
				<origin xyz="0 0 0" rpy="0 0 0" />
				<geometry name="ADE_pitch_shoulder${side}_fixation_visual_geom">
					<sphere radius="0.001" />
				</geometry>
			</visual>

			<collision>
				<origin xyz="0 0 0" rpy="0 0 0 " />
				<geometry name="ADE_pitch_shoulder${side}_fixation_collision_geom">
					<sphere radius="0.001" />
				</geometry>
			</collision>
		</link>

		<joint name="ADE_pitch_shoulder${side}_fixed_2_joint" type="fixed">
			<parent link="ADE_pitch_shoulder${side}_fixation"/>
			<child link="ADE_pitch_shoulder${side}_box"/>
			<origin xyz="0.05 0 -0.03" rpy="0 -0.7854 0" />
		</joint>

		<link name="ADE_pitch_shoulder${side}_box">
			<inertial>
				<mass value="1.105" />
				<origin xyz="0 0 0" rpy="0 0 0"/> 
        <inertia  ixx="0.002790566518" ixy="0.00"  ixz="0.00"
                  iyy="0.002862829183" iyz="0.00"
                  izz="0.001375984901" />
			</inertial>

			<visual>
				<origin xyz="0 0 0" rpy="0 0 0" />
				<geometry name="ADE_pitch_shoulder${side}_box_visual_geom">
					<box size="0.088678 0.084137 0.1524" />
				</geometry>
			</visual>

			<collision>
				<origin xyz="0 0 0" rpy="0 0 0 " />
				<geometry name="ADE_pitch_shoulder${side}_box_collision_geom">
					<box size="0.088678 0.084137 0.1524" />
				</geometry>
			</collision>
		</link>
		
		<!-- extensions -->
		<xacro:jn0_ADE_pitch_shoulder_transmission side="${side}" />
		
		<gazebo reference="ADE_pitch_shoulder${side}_link">
			<material>Gazebo/Red</material>
		</gazebo>

		<gazebo reference="ADE_pitch_shoulder${side}_box">
			<material>Gazebo/Blue</material>
		</gazebo>
		
	</xacro:macro>

</robot>
