<?xml version="1.0"?>
<robot xmlns:sensor="http://playerstage.sourceforge.net/gazebo/xmlschema/#sensor"
       xmlns:controller="http://playerstage.sourceforge.net/gazebo/xmlschema/#controller"
       xmlns:interface="http://playerstage.sourceforge.net/gazebo/xmlschema/#interface"
       xmlns:xacro="http://ros.org/wiki/xacro">

	<xacro:include filename="$(find irl_common_description)/urdf/reddy_arm/arm.transmission.xacro" />
	
	<xacro:macro name="reddy_arm_elbow_pitch" params="name reflect parent">

		<link name="${name}_box">
			<inertial>
				<mass value="1.105" />
				<origin xyz="0 0 0" rpy="0 0 0"/> 
        <inertia  ixx="0.002790566518" ixy="0.00"  ixz="0.00"
                  iyy="0.002862829183" iyz="0.00"
                  izz="0.001375984901" />
			</inertial>

			<visual>
				<origin xyz="0 0 0" rpy="0 0 0" />
				<geometry name="${name}_box_visual_geom">
					<box size="0.088678 0.084137 0.1524" />
				</geometry>
				<material name="${name}_color">
					<color rgba="0 0 1 1"/>
				</material>
			</visual>

			<collision>
				<origin xyz="0 0 0" rpy="0 0 0 " />
				<geometry name="${name}_box_collision_geom">
					<box size="0.088678 0.084137 0.1524" />
				</geometry>
			</collision>
		</link>

		<link name="${name}_fixation">
			<inertial>
				<mass value="0.001" />
				<origin xyz="0 0 0" rpy="0 0 0"/> 
        <inertia  ixx="0.00" ixy="0.00"  ixz="0.00"
                  iyy="0.00" iyz="0.00"
                  izz="0.00" />
			</inertial>

			<visual>
				<origin xyz="0 0 0" rpy="0 0 0" />
				<geometry name="${name}_fixation_visual_geom">
					<sphere radius="0.001" />
				</geometry>
			</visual>

			<collision>
				<origin xyz="0 0 0" rpy="0 0 0 " />
				<geometry name="${name}_fixation_collision_geom">
					<sphere radius="0.001" />
				</geometry>
			</collision>
		</link>
		
		<link name="${name}_link">
			<inertial>
				<mass value="0.045" />
				<origin xyz="0 0 0" rpy="0 0 0"/> 
        <inertia  ixx="0.00" ixy="0.00"  ixz="0.00"
                  iyy="0.00" iyz="0.00"
                  izz="0.00" />
			</inertial>

			<visual>
				<origin xyz="0 0 0" rpy="0 0 0" />
				<geometry name="${name}_link_visual_geom">
					<box size="0.047 0.01 0.01" />
				</geometry>
			</visual>

			<collision>
				<origin xyz="0 0 0" rpy="0 0 0 " />
				<geometry name="${name}_link_collision_geom">
					<box size="0.047 0.01 0.01" />
				</geometry>
			</collision>
		</link>
		
		
		<joint name="${name}_fixed_1_joint" type="fixed">
			<parent link="${parent}"/>
			<child link="${name}_box"/>
			<origin xyz="0 0 -0.1524" rpy="0 0 ${(reflect-1)*M_PI/2}" />
		</joint>

		<joint name="${name}_revolute_joint" type="revolute">
			<parent link="${name}_box"/>
			<child link="${name}_fixation"/>
			<origin xyz="0 -0.03 -0.05" rpy="0 0 -1.5708" />
			<axis xyz="0 1 0" rpy="0 0 0"/>
			<limit effort="100" velocity="0.1" lower="0" upper="1.5708" />

			<!-- calibration reference_position="0.0"/ -->
		</joint>

		<joint name="${name}_fixed_2_joint" type="fixed">
			<parent link="${name}_fixation"/>
			<child link="${name}_link"/>
			<origin xyz="0.0235 0 0" rpy="0 0 0" />
		</joint>
		
		<!-- extensions -->
		<xacro:reddy_arm_elbow_pitch_transmission name="${name}_trans" />
		
		<gazebo reference="${name}_box">
			<material>Gazebo/Green</material>
		</gazebo>

		<gazebo reference="${name}_link">
			<material>Gazebo/Red</material>
		</gazebo>
		
	</xacro:macro>

</robot>
