<?xml version="1.0"?>

<!-- XML namespaces -->
<robot xmlns:xacro="http://www.ros.org/wiki/xacro">

	<!-- Things that are needed only for Gazebo (not the physical robot).  These include
	sensor and controller plugin specifications -->
	<xacro:include filename="$(find irl_common_description)/urdf/jn0_arm/shoulder/shoulder.gazebo.xacro" />
	<xacro:include filename="$(find irl_common_description)/urdf/jn0_arm/shoulder/shoulder.transmission.xacro" />
	<xacro:include filename="$(find irl_common_description)/urdf/common.xacro" />

	<!-- ============================   Shoulder   ============================ -->

	<xacro:macro name="johnny_0_shoulder" params="side parent reflect *origin">

		<!-- Shoulder fixed joint -->

		<joint name="${side}_shoulder_fixed_joint" type="fixed">
			<xacro:insert_block name="origin" />
			<parent link="${parent}"/>
			<child link="${side}_shoulder_fixed_link"/>
		</joint>

		<!-- Shoulder fixed link -->

		<link name="${side}_shoulder_fixed_link">
			<inertial>
				<mass value="1.19220892" />
				<origin xyz="-0.00000272 -0.01235088 -0.09031596" rpy="0 0 0"/> 
				<inertia  	ixx="0.00337306" 	ixy="0.00000002"  	ixz="0.0"
										iyy="0.00266910" 	iyz="-0.00086743"
														izz="0.00211447" />
			</inertial>

			<visual>
				<origin xyz="0 0 0" rpy="0 0 0" />
				<geometry name="${side}_shoulder_fixed_link_visual_geom">
					<mesh filename="package://irl_common_description/meshes/jn0_arm/shoulder/${side}_shoulder_fixed_link.dae"  />
				</geometry>
			</visual>

			<collision>
				<origin xyz="0 0 0" rpy="0 0 0 " />
				<geometry name="${side}_shoulder_fixed_link_collision_geom">
					<mesh filename="package://irl_common_description/meshes/jn0_arm/shoulder/${side}_shoulder_fixed_link.stl"  />
				</geometry>
			</collision>
		</link>
		
		<!-- Shoulder revolute joint - axis 1 : pan -->
		
		<joint name="${side}_shoulder_pan_joint" type="revolute">
		<!--joint name="${side}_shoulder_pan_joint" type="continuous"-->
		<!--joint name="${side}_shoulder_pan_joint" type="fixed"-->
			<axis xyz="0 0 1" />
			<origin xyz="0 0 0" rpy="0 0 0" />
			<parent link="${side}_shoulder_fixed_link"/>
			<child link="${side}_shoulder_pan_link"/>
		
			<!-- This parameters have to be modified -->
			<limit effort="30" velocity="2.0" lower="${-M_PI/2}" upper="${M_PI/2}" />
			<!--safety_controller k_position="100" k_velocity="10" soft_lower_limit="${-M_PI/2+0.15}" soft_upper_limit="${M_PI/2-0.15}"  /-->
		</joint>

		<!-- Shoulder link - First mobile part of the shoulder (pan) -->

		<link name="${side}_shoulder_pan_link">
			<inertial>
				<mass value="1.5029103" />
				<origin xyz="-0.00000458 0.03120604 -0.02992782" rpy="0 0 0"/> 
				<inertia  	ixx="0.00431624" 	ixy="0.00000015"  	ixz="-0.00000011"
										iyy="0.00240441" 	iyz="0.00139880"
														izz="0.00251981" />
			</inertial>

			<visual>
				<origin xyz="0 0 0" rpy="0 0 0"/>
				<geometry name="${side}_shoulder_pan_link_visual_geom">
					<mesh filename="package://irl_common_description/meshes/jn0_arm/shoulder/${side}_shoulder_pan_link.dae"  />
				</geometry>
			</visual>

			<collision>
				<origin xyz="0 0 0" rpy="0 0 0"/>
				<geometry name="${side}_shoulder_pan_link_collision_geom">
					<mesh filename="package://irl_common_description/meshes/jn0_arm/shoulder/${side}_shoulder_pan_link.stl"  />
				</geometry>
			</collision>
		</link>
		
		<!-- Shoulder revolute joint - axis 2 : tilt -->
		
		<joint name="${side}_shoulder_tilt_joint" type="revolute">
		<!--joint name="${side}_shoulder_tilt_joint" type="continuous"-->
		<!--joint name="${side}_shoulder_tilt_joint" type="fixed"-->
			<axis xyz="0 0 1" />
			<origin xyz="0 ${reflect*0.09471141} 0" rpy="${-M_PI/2} 0 0"/>
			<parent link="${side}_shoulder_pan_link"/>
			<child link="${side}_shoulder_tilt_link"/>
		
			<!-- This parameters have to be modified -->
			<!--limit effort="30" velocity="2.0" lower="${-M_PI/2}" upper="${M_PI}" /-->
			<limit effort="30" velocity="2.0" lower="${-M_PI}" upper="${M_PI/2}" />
			<!--safety_controller k_position="100" k_velocity="10" soft_lower_limit="${-M_PI/2}" soft_upper_limit="${M_PI}"/-->
		</joint>
		
		<!-- Shoulder link -->
		<link name="${side}_shoulder_tilt_link">
			<inertial>
				<mass value="1.77083411" />
				<origin xyz="-0.00690346 0.03925534 0.00828557" rpy="0 0 0"/> 
				<inertia  	ixx="0.00639093" 	ixy="-0.00121012"  ixz="0.00025902"
										iyy="0.00353925" 	iyz="-0.00029889"
														izz="0.00626044" />
			</inertial>

			<visual>
				<origin xyz="0 0 0" rpy="0 0 0"/>
				<geometry name="${side}_shoulder_tilt_link_visual_geom">
					<mesh filename="package://irl_common_description/meshes/jn0_arm/shoulder/${side}_shoulder_tilt_link.dae"  />
				</geometry>
			</visual>

			<collision>
				<origin xyz="0 0 0" rpy="0 0 0"/>
				<geometry name="${side}_shoulder_tilt_link_collision_geom">
					<mesh filename="package://irl_common_description/meshes/jn0_arm/shoulder/${side}_shoulder_tilt_link.stl"  />
				</geometry>
			</collision>
		</link>
		
		<!-- extensions -->
		
		<xacro:johnny_0_shoulder_transmission reflect="${reflect}" side="${side}" />
		
	</xacro:macro>


</robot>
